<?xml version="1.0"?>
<robot xmlns:xacro="http://ros.org/wiki/xacro" name="photo_station_v2">
  
  <!-- Base link -->
  <link name="base_link">
    <visual>
      <geometry>
        <box size="0.1 0.1 0.1"/>
      </geometry>
      <material name="blue">
        <color rgba="0 0 1 1"/>
      </material>
    </visual>
    <inertial>
      <mass value="1.0"/>
      <inertia ixx="0.01" ixy="0" ixz="0" iyy="0.01" iyz="0" izz="0.01"/>
    </inertial>
  </link>
  
  <!-- Link 1 -->
  <link name="link1">
    <visual>
      <geometry>
        <cylinder radius="0.05" length="0.2"/>
      </geometry>
      <material name="red">
        <color rgba="1 0 0 1"/>
      </material>
    </visual>
    <inertial>
      <mass value="0.5"/>
      <inertia ixx="0.005" ixy="0" ixz="0" iyy="0.005" iyz="0" izz="0.005"/>
    </inertial>
  </link>
  
  <!-- Link 2 -->
  <link name="link2">
    <visual>
      <geometry>
        <cylinder radius="0.05" length="0.2"/>
      </geometry>
      <material name="green">
        <color rgba="0 1 0 1"/>
      </material>
    </visual>
    <inertial>
      <mass value="0.5"/>
      <inertia ixx="0.005" ixy="0" ixz="0" iyy="0.005" iyz="0" izz="0.005"/>
    </inertial>
  </link>
  
  <!-- Joint 1 -->
  <joint name="joint1" type="revolute">
    <parent link="base_link"/>
    <child link="link1"/>
    <origin xyz="0.08 -0.035 0" rpy="0 0 0"/>
    <axis xyz="0 1 0"/>
    <limit lower="-100000" upper="100000" effort="10" velocity="30"/>
  </joint>
  
  <!-- Joint 2 -->
  <joint name="joint2" type="revolute">
    <parent link="link1"/>
    <child link="link2"/>
    <origin xyz="0.08 -0.035 0" rpy="0 0 0"/>
    <axis xyz="0 1 0"/>
    <limit lower="-100000" upper="100000" effort="10" velocity="30"/>
  </joint>
  
  <!-- ROS2 Control Hardware Interface -->
  <ros2_control name="photo_station_v2_hardware" type="system">
    <hardware>
      <plugin>actuator_interface/Ros2ControlHw</plugin>
      <param name="config_file">$(find photo_station_v2)/config/photo_station_v2_hw.yaml</param>
    </hardware>
    
    <joint name="joint1">
      <command_interface name="effort"/>
      <state_interface name="position"/>
      <state_interface name="velocity"/>
      <state_interface name="effort"/>
    </joint>
    
    <joint name="joint2">
      <command_interface name="effort"/>
      <state_interface name="position"/>
      <state_interface name="velocity"/>
      <state_interface name="effort"/>
    </joint>
  </ros2_control>
  
</robot> 